2024-05-13 15:08:51,552 CRIT Supervisor is running as root.  Privileges were not dropped because no user is specified in the config file.  If you intend to run as root, you can set user=root in the config file to avoid this message.
2024-05-13 15:08:51,553 INFO supervisord started with pid 7
2024-05-13 15:08:52,556 INFO spawned: 'app' with pid 8
2024-05-13 15:08:52,558 INFO spawned: 'nginx' with pid 9
Traceback (most recent call last):
  File "/app/main.py", line 8, in <module>
    import states
  File "/app/states.py", line 5, in <module>
    from data_fetching import DataFetcher, ValidationDataFetcher
ModuleNotFoundError: No module named 'data_fetching'
2024-05-13 15:08:52,726 WARN exited: app (exit status 1; not expected)
2024-05-13 15:08:53,729 INFO spawned: 'app' with pid 49
2024-05-13 15:08:53,730 INFO success: nginx entered RUNNING state, process has stayed up for > than 1 seconds (startsecs)
Traceback (most recent call last):
  File "/app/main.py", line 8, in <module>
    import states
  File "/app/states.py", line 5, in <module>
    from data_fetching import DataFetcher, ValidationDataFetcher
ModuleNotFoundError: No module named 'data_fetching'
2024-05-13 15:08:53,899 WARN exited: app (exit status 1; not expected)
2024-05-13 15:08:56,900 INFO spawned: 'app' with pid 69
Traceback (most recent call last):
  File "/app/main.py", line 8, in <module>
    import states
  File "/app/states.py", line 5, in <module>
    from data_fetching import DataFetcher, ValidationDataFetcher
ModuleNotFoundError: No module named 'data_fetching'
2024-05-13 15:08:58,062 INFO success: app entered RUNNING state, process has stayed up for > than 1 seconds (startsecs)
2024-05-13 15:08:58,062 WARN exited: app (exit status 1; not expected)
2024-05-13 15:08:59,064 INFO spawned: 'app' with pid 89
Traceback (most recent call last):
  File "/app/main.py", line 8, in <module>
    import states
  File "/app/states.py", line 5, in <module>
    from data_fetching import DataFetcher, ValidationDataFetcher
ModuleNotFoundError: No module named 'data_fetching'
2024-05-13 15:08:59,254 WARN exited: app (exit status 1; not expected)
2024-05-13 15:09:00,257 INFO spawned: 'app' with pid 109
Traceback (most recent call last):
  File "/app/main.py", line 8, in <module>
    import states
  File "/app/states.py", line 5, in <module>
    from data_fetching import DataFetcher, ValidationDataFetcher
ModuleNotFoundError: No module named 'data_fetching'
2024-05-13 15:09:00,423 WARN exited: app (exit status 1; not expected)
2024-05-13 15:09:02,427 INFO spawned: 'app' with pid 129
Traceback (most recent call last):
  File "/app/main.py", line 8, in <module>
    import states
  File "/app/states.py", line 5, in <module>
    from data_fetching import DataFetcher, ValidationDataFetcher
ModuleNotFoundError: No module named 'data_fetching'
2024-05-13 15:09:02,596 WARN exited: app (exit status 1; not expected)
2024-05-13 15:09:05,600 INFO spawned: 'app' with pid 149
Traceback (most recent call last):
  File "/app/main.py", line 8, in <module>
    import states
  File "/app/states.py", line 5, in <module>
    from data_fetching import DataFetcher, ValidationDataFetcher
ModuleNotFoundError: No module named 'data_fetching'
2024-05-13 15:09:05,779 WARN exited: app (exit status 1; not expected)
2024-05-13 15:09:06,780 INFO gave up: app entered FATAL state, too many start retries too quickly
